Workbook
Name UPDATE: 'Data Sheet'!$E$1

Sheet Alyman's Z Score
B4: ='Data Sheet'!B1 -> AVENUE SUPERMARTS LTD
B7: =CONCATENATE(" ","INR "&'Data Sheet'!B8) -> INR 4358.2
B8: 52 Week (High- INR 5,484.85 & Low - INR 3,340.00)
B10: Altman's Z Score Analysis
B11: Avenue Supermarts Limited, DMart, is an Indian retail corporation that operates a chain of supermarkets and hypermarkets. The company was founded by Radhakishan Damani and is based in Mumbai. As of March 2025, DMart has 415 stores across 12 states and union territories in India] In March 2024, the company had a total of 13,971 permanent employees and 59,961 employees hired on contractual basis
B17: Summery
B42: =B46 -> Working Capital/Total Asset
C43: ='Raw FS'!F2 -> 42795 | D43: ='Raw FS'!G2 -> 43160 | E43: ='Raw FS'!H2 -> 43525 | F43: ='Raw FS'!I2 -> 43891 | G43: ='Raw FS'!J2 -> 44256 | H43: ='Raw FS'!K2 -> 44621 | I43: ='Raw FS'!L2 -> 44986 | J43: ='Raw FS'!M2 -> 45352 | K43: ='Raw FS'!N2 -> 45717
B44: Working Capital | C44: ='Data Sheet'!C65-'Data Sheet'!C60 -> 2582.77 | D44: ='Data Sheet'!D65-'Data Sheet'!D60 -> 1493.08 | E44: ='Data Sheet'!E65-'Data Sheet'!E60 -> 1493.86 | F44: ='Data Sheet'!F65-'Data Sheet'!F60 -> 5085.82 | G44: ='Data Sheet'!G65-'Data Sheet'!G60 -> 4545.08 | H44: ='Data Sheet'!H65-'Data Sheet'!H60 -> 3929.28 | I44: ='Data Sheet'!I65-'Data Sheet'!I60 -> 4349.84 | J44: ='Data Sheet'!J65-'Data Sheet'!J60 -> 4833.09 | K44: ='Data Sheet'!K65-'Data Sheet'!K60 -> 4938.3
B45: Total Asset | C45: ='Data Sheet'!C61 -> 5819.28 | D45: ='Data Sheet'!D61 -> 5648.22 | E45: ='Data Sheet'!E61 -> 7005.5 | F45: ='Data Sheet'!F61 -> 12076.16 | G45: ='Data Sheet'!G61 -> 13655.05 | H45: ='Data Sheet'!H61 -> 15470.98 | I45: ='Data Sheet'!I61 -> 18104.52 | J45: ='Data Sheet'!J61 -> 21172.48 | K45: ='Data Sheet'!K61 -> 24312.78
B46: Working Capital/Total Asset | C46: =C44/C45 -> 0.44382982 | D46: =D44/D45 -> 0.26434523 | E46: =E44/E45 -> 0.21324102 | F46: =F44/F45 -> 0.42114546 | G46: =G44/G45 -> 0.33284975 | H46: =H44/H45 -> 0.25397745 | I46: =I44/I45 -> 0.24026265 | J46: =J44/J45 -> 0.22827227 | K46: =K44/K45 -> 0.2031154
B48: =B52 -> Reatain Earning / Total Asset
C49: =C43 -> 42795 | D49: =D43 -> 43160 | E49: =E43 -> 43525 | F49: =F43 -> 43891 | G49: =G43 -> 44256 | H49: =H43 -> 44621 | I49: =I43 -> 44986 | J49: =J43 -> 45352 | K49: =K43 -> 45717
B50: Retain Earning | C50: =HistoricaIFS!D35*HistoricaIFS!D37*HistoricaIFS!D43 -> 478.75 | D50: =HistoricaIFS!E35*HistoricaIFS!E37*HistoricaIFS!E43 -> 806.26 | E50: =HistoricaIFS!F35*HistoricaIFS!F37*HistoricaIFS!F43 -> 902.54 | F50: =HistoricaIFS!G35*HistoricaIFS!G37*HistoricaIFS!G43 -> 1301.08 | G50: =HistoricaIFS!H35*HistoricaIFS!H37*HistoricaIFS!H43 -> 1099.49 | H50: =HistoricaIFS!I35*HistoricaIFS!I37*HistoricaIFS!I43 -> 1492.55 | I50: =HistoricaIFS!J35*HistoricaIFS!J37*HistoricaIFS!J43 -> 2378.51 | J50: =HistoricaIFS!K35*HistoricaIFS!K37*HistoricaIFS!K43 -> 2536.17 | K50: =HistoricaIFS!L35*HistoricaIFS!L37*HistoricaIFS!L43 -> 2708.02
B51: Total Asset | C51: =C45 -> 5819.28 | D51: =D45 -> 5648.22 | E51: =E45 -> 7005.5 | F51: =F45 -> 12076.16 | G51: =G45 -> 13655.05 | H51: =H45 -> 15470.98 | I51: =I45 -> 18104.52 | J51: =J45 -> 21172.48 | K51: =K45 -> 24312.78
B52: Reatain Earning / Total Asset | C52: =C50/C51 -> 0.082269628 | D52: =D50/D51 -> 0.14274586 | E52: =E50/E51 -> 0.12883306 | F52: =F50/F51 -> 0.10773955 | G52: =G50/G51 -> 0.080518929 | H52: =H50/H51 -> 0.096474173 | I52: =I50/I51 -> 0.13137658 | J52: =J50/J51 -> 0.11978616 | K52: =K50/K51 -> 0.11138257
B54: EBIT / Total Asset
B56: EBIT | C56: ='Data Sheet'!C28+'Data Sheet'!C27 -> 869.06 | D56: ='Data Sheet'!D28+'Data Sheet'!D27 -> 1281.61 | E56: ='Data Sheet'!E28+'Data Sheet'!E27 -> 1469.15 | F56: ='Data Sheet'!F28+'Data Sheet'!F27 -> 1813.89 | G56: ='Data Sheet'!G28+'Data Sheet'!G27 -> 1525.1 | H56: ='Data Sheet'!H28+'Data Sheet'!H27 -> 2117.91 | I56: ='Data Sheet'!I28+'Data Sheet'!I27 -> 3127.5 | J56: ='Data Sheet'!J28+'Data Sheet'!J27 -> 3519.46 | K56: ='Data Sheet'!K28+'Data Sheet'!K27 -> 3742.12
B57: Total Asset | C57: =C45 -> 5819.28 | D57: =D45 -> 5648.22 | E57: =E45 -> 7005.5 | F57: =F45 -> 12076.16 | G57: =G45 -> 13655.05 | H57: =H45 -> 15470.98 | I57: =I45 -> 18104.52 | J57: =J45 -> 21172.48 | K57: =K45 -> 24312.78
B58: EBIT/ Total Asset | C58: =C56/C57 -> 0.1493415 | D58: =D56/D57 -> 0.22690511 | E58: =E56/E57 -> 0.2097138 | F58: =F56/F57 -> 0.1502042 | G58: =G56/G57 -> 0.11168762 | H58: =H56/H57 -> 0.13689566 | I58: =I56/I57 -> 0.17274692 | J58: =J56/J57 -> 0.16622805 | K58: =K56/K57 -> 0.15391576
B60: Market Cap /Long Term Liablities
B62: Market Cap(Cr) | C62: =('Data Sheet'!C90*'Data Sheet'!C70)/10000000 -> 39807.229 | D62: =('Data Sheet'!D90*'Data Sheet'!D70)/10000000 -> 82678.713 | E62: =('Data Sheet'!E90*'Data Sheet'!E70)/10000000 -> 91809.069 | F62: =('Data Sheet'!F90*'Data Sheet'!F70)/10000000 -> 141700.71 | G62: =('Data Sheet'!G90*'Data Sheet'!G70)/10000000 -> 185202.02 | H62: =('Data Sheet'!H90*'Data Sheet'!H70)/10000000 -> 259326.88 | I62: =('Data Sheet'!I90*'Data Sheet'!I70)/10000000 -> 220477.82 | J62: =('Data Sheet'!J90*'Data Sheet'!J70)/10000000 -> 294495.76 | K62: =('Data Sheet'!K90*'Data Sheet'!K70)/10000000 -> 265707.33
B63: Long term Liablities | C63: ='Data Sheet'!C59 -> 1497.32 | D63: ='Data Sheet'!D59 -> 439.25 | E63: ='Data Sheet'!E59 -> 700.15 | F63: ='Data Sheet'!F59 -> 333.19 | G63: ='Data Sheet'!G59 -> 392.71 | H63: ='Data Sheet'!H59 -> 646.94 | I63: ='Data Sheet'!I59 -> 642.98 | J63: ='Data Sheet'!J59 -> 592.16 | K63: ='Data Sheet'!K59 -> 819.62
B64: =B60 -> Market Cap /Long Term Liablities | C64: =C62/C63 -> 26.585652 | D64: =D62/D63 -> 188.22701 | E64: =E62/E63 -> 131.12771 | F64: =F62/F63 -> 425.28501 | G64: =G62/G63 -> 471.59997 | H64: =H62/H63 -> 400.85152 | I64: =I62/I63 -> 342.89997 | J64: =J62/J63 -> 497.32464 | K64: =K62/K63 -> 324.18356
B68: Total Sales/ Total Asset
C69: =C43 -> 42795 | D69: =D43 -> 43160 | E69: =E43 -> 43525 | F69: =F43 -> 43891 | G69: =G43 -> 44256 | H69: =H43 -> 44621 | I69: =I43 -> 44986 | J69: =J43 -> 45352 | K69: =K43 -> 45717
B70: Sales | C70: ='Data Sheet'!C17 -> 11897.7 | D70: ='Data Sheet'!D17 -> 15033.2 | E70: ='Data Sheet'!E17 -> 20004.52 | F70: ='Data Sheet'!F17 -> 24870.2 | G70: ='Data Sheet'!G17 -> 24143.06 | H70: ='Data Sheet'!H17 -> 30976.27 | I70: ='Data Sheet'!I17 -> 42839.56 | J70: ='Data Sheet'!J17 -> 50788.83 | K70: ='Data Sheet'!K17 -> 59358.05
B71: =B57 -> Total Asset | C71: =C45 -> 5819.28 | D71: =D45 -> 5648.22 | E71: =E45 -> 7005.5 | F71: =F45 -> 12076.16 | G71: =G45 -> 13655.05 | H71: =H45 -> 15470.98 | I71: =I45 -> 18104.52 | J71: =J45 -> 21172.48 | K71: =K45 -> 24312.78
B72: =B68 -> Total Sales/ Total Asset | C72: =C70/C71 -> 2.0445313 | D72: =D70/D71 -> 2.6615819 | E72: =E70/E71 -> 2.8555449 | F72: =F70/F71 -> 2.059446 | G72: =G70/G71 -> 1.7680682 | H72: =H70/H71 -> 2.0022177 | I72: =I70/I71 -> 2.3662356 | J72: =J70/J71 -> 2.3988135 | K72: =K70/K71 -> 2.4414341
B74: Altman's Z Score
C75: =C69 -> 42795 | D75: =D69 -> 43160 | E75: =E69 -> 43525 | F75: =F69 -> 43891 | G75: =G69 -> 44256 | H75: =H69 -> 44621 | I75: =I69 -> 44986 | J75: =J69 -> 45352 | K75: =K69 -> 45717
B76: Final Score | C76: =(C46*1.2)+(C52*1.4)+(C58*3.3)+(C64*0.6)+(C72*1) -> 19.136523 | D76: =(D46*1.2)+(D52*1.4)+(D58*3.3)+(D64*0.6)+(D72*1) -> 116.86363 | E76: =(E46*1.2)+(E52*1.4)+(E58*3.3)+(E64*0.6)+(E72*1) -> 82.660484 | F76: =(F46*1.2)+(F52*1.4)+(F58*3.3)+(F64*0.6)+(F72*1) -> 258.38234 | G76: =(G46*1.2)+(G52*1.4)+(G58*3.3)+(G64*0.6)+(G72*1) -> 285.60876 | H76: =(H46*1.2)+(H52*1.4)+(H58*3.3)+(H64*0.6)+(H72*1) -> 243.40472 | I76: =(I46*1.2)+(I52*1.4)+(I58*3.3)+(I64*0.6)+(I72*1) -> 209.14852 | J76: =(J46*1.2)+(J52*1.4)+(J58*3.3)+(J64*0.6)+(J72*1) -> 301.78378 | K76: =(K46*1.2)+(K52*1.4)+(K58*3.3)+(K64*0.6)+(K72*1) -> 197.85916
B77: Finacial Stability | C77: =IF(C76<1.8,"Distressed",IF(C76>3,"Strong","GreyZone")) -> Strong | D77: =IF(D76<1.8,"Distressed",IF(D76>3,"Strong","GreyZone")) -> Strong | E77: =IF(E76<1.8,"Distressed",IF(E76>3,"Strong","GreyZone")) -> Strong | F77: =IF(F76<1.8,"Distressed",IF(F76>3,"Strong","GreyZone")) -> Strong | G77: =IF(G76<1.8,"Distressed",IF(G76>3,"Strong","GreyZone")) -> Strong | H77: =IF(H76<1.8,"Distressed",IF(H76>3,"Strong","GreyZone")) -> Strong | I77: =IF(I76<1.8,"Distressed",IF(I76>3,"Strong","GreyZone")) -> Strong | J77: =IF(J76<1.8,"Distressed",IF(J76>3,"Strong","GreyZone")) -> Strong | K77: =IF(K76<1.8,"Distressed",IF(K76>3,"Strong","GreyZone")) -> Strong

Sheet Profit & Loss
A1: ='Data Sheet'!B1 -> AVENUE SUPERMARTS LTD | H1: =UPDATE | M1: SCREENER.IN
A3: Narration | B3: ='Data Sheet'!B16 -> 42460 | C3: ='Data Sheet'!C16 -> 42825 | D3: ='Data Sheet'!D16 -> 43190 | E3: ='Data Sheet'!E16 -> 43555 | F3: ='Data Sheet'!F16 -> 43921 | G3: ='Data Sheet'!G16 -> 44286 | H3: ='Data Sheet'!H16 -> 44651 | I3: ='Data Sheet'!I16 -> 45016 | ... K3: ='Data Sheet'!K16 -> 45747 | L3: Trailing | M3: Best Case | N3: Worst Case
A4: Sales | B4: ='Data Sheet'!B17 -> 8583.76 | C4: ='Data Sheet'!C17 -> 11897.7 | D4: ='Data Sheet'!D17 -> 15033.2 | E4: ='Data Sheet'!E17 -> 20004.52 | F4: ='Data Sheet'!F17 -> 24870.2 | G4: ='Data Sheet'!G17 -> 24143.06 | H4: ='Data Sheet'!H17 -> 30976.27 | I4: ='Data Sheet'!I17 -> 42839.56 | ... K4: ='Data Sheet'!K17 -> 59358.05 | L4: =SUM(Quarters!H4:K4) -> 61648.61 | M4: =$K4+M23*K4 -> 73727.548 | N4: =$K4+N23*L4 -> 69759.56
A5: Expenses | B5: =SUM('Data Sheet'!B18,'Data Sheet'!B20:B24, -1*'Data Sheet'!B19) -> 7919.3 | C5: =SUM('Data Sheet'!C18,'Data Sheet'!C20:C24, -1*'Data Sheet'!C19) -> 10928.52 | D5: =SUM('Data Sheet'!D18,'Data Sheet'!D20:D24, -1*'Data Sheet'!D19) -> 13680.34 | E5: =SUM('Data Sheet'!E18,'Data Sheet'!E20:E24, -1*'Data Sheet'!E19) -> 18371.21 | F5: =SUM('Data Sheet'!F18,'Data Sheet'!F20:F24, -1*'Data Sheet'!F19) -> 22741.89 | G5: =SUM('Data Sheet'!G18,'Data Sheet'!G20:G24, -1*'Data Sheet'!G19) -> 22398.23 | H5: =SUM('Data Sheet'!H18,'Data Sheet'!H20:H24, -1*'Data Sheet'!H19) -> 28473.92 | I5: =SUM('Data Sheet'!I18,'Data Sheet'!I20:I24, -1*'Data Sheet'!I19) -> 39200.79 | ... K5: =SUM('Data Sheet'!K18,'Data Sheet'!K20:K24, -1*'Data Sheet'!K19) -> 54863.54 | L5: =SUM(Quarters!H5:K5) -> 57083.49 | M5: =M4-M6 -> 67829.342 | N5: =N4-N6 -> 64593.818
A6: Operating Profit | B6: =B4-B5 -> 664.46 | C6: =C4-C5 -> 969.18 | D6: =D4-D5 -> 1352.86 | E6: =E4-E5 -> 1633.31 | F6: =F4-F5 -> 2128.31 | G6: =G4-G5 -> 1744.83 | H6: =H4-H5 -> 2502.35 | I6: =I4-I5 -> 3638.77 | ... K6: =K4-K5 -> 4494.51 | L6: =SUM(Quarters!H6:K6) -> 4565.12 | M6: =M4*M24 -> 5898.2062 | N6: =N4*N24 -> 5165.7411
A7: Other Income | B7: ='Data Sheet'!B25 -> 17.02 | C7: ='Data Sheet'!C25 -> 27.7 | D7: ='Data Sheet'!D25 -> 87.75 | E7: ='Data Sheet'!E25 -> 48.33 | F7: ='Data Sheet'!F25 -> 59.99 | G7: ='Data Sheet'!G25 -> 194.43 | H7: ='Data Sheet'!H25 -> 113.64 | I7: ='Data Sheet'!I25 -> 127.6 | ... K7: ='Data Sheet'!K25 -> 117.13 | L7: =SUM(Quarters!H7:K7) -> 102.14 | M7: 0 | N7: 0
A8: Depreciation | B8: ='Data Sheet'!B26 -> 98.43 | C8: ='Data Sheet'!C26 -> 127.82 | D8: ='Data Sheet'!D26 -> 159 | E8: ='Data Sheet'!E26 -> 212.49 | F8: ='Data Sheet'!F26 -> 374.41 | G8: ='Data Sheet'!G26 -> 414.16 | H8: ='Data Sheet'!H26 -> 498.08 | I8: ='Data Sheet'!I26 -> 638.87 | ... K8: ='Data Sheet'!K26 -> 869.52 | L8: =SUM(Quarters!H8:K8) -> 908.46 | M8: =+$L8 -> 908.46 | N8: =+$L8 -> 908.46
A9: Interest | B9: ='Data Sheet'!B27 -> 91.34 | C9: ='Data Sheet'!C27 -> 121.98 | D9: ='Data Sheet'!D27 -> 59.54 | E9: ='Data Sheet'!E27 -> 47.21 | F9: ='Data Sheet'!F27 -> 69.12 | G9: ='Data Sheet'!G27 -> 41.65 | H9: ='Data Sheet'!H27 -> 53.79 | I9: ='Data Sheet'!I27 -> 67.41 | ... K9: ='Data Sheet'!K27 -> 69.45 | L9: =SUM(Quarters!H9:K9) -> 82.79 | M9: =+$L9 -> 82.79 | N9: =+$L9 -> 82.79
A10: Profit before tax | B10: ='Data Sheet'!B28 -> 491.71 | C10: ='Data Sheet'!C28 -> 747.08 | D10: ='Data Sheet'!D28 -> 1222.07 | E10: ='Data Sheet'!E28 -> 1421.94 | F10: ='Data Sheet'!F28 -> 1744.77 | G10: ='Data Sheet'!G28 -> 1483.45 | H10: ='Data Sheet'!H28 -> 2064.12 | I10: ='Data Sheet'!I28 -> 3060.09 | ... K10: ='Data Sheet'!K28 -> 3672.67 | L10: =SUM(Quarters!H10:K10) -> 3676.01 | M10: =M6+M7-SUM(M8:M9) -> 4906.9562 | N10: =N6+N7-SUM(N8:N9) -> 4174.4911
A11: Tax | B11: ='Data Sheet'!B29 -> 171.47 | C11: ='Data Sheet'!C29 -> 268.28 | D11: ='Data Sheet'!D29 -> 415.79 | E11: ='Data Sheet'!E29 -> 519.48 | F11: ='Data Sheet'!F29 -> 443.79 | G11: ='Data Sheet'!G29 -> 384.02 | H11: ='Data Sheet'!H29 -> 571.72 | I11: ='Data Sheet'!I29 -> 681.75 | ... K11: ='Data Sheet'!K29 -> 965.22 | L11: =SUM(Quarters!H11:K11) -> 969.43 | M11: =IF($L10>0,$L11/$L10,0) -> 0.263718 | N11: =IF($L10>0,$L11/$L10,0) -> 0.263718
A12: Net profit | B12: ='Data Sheet'!B30 -> 320.24 | C12: ='Data Sheet'!C30 -> 478.75 | D12: ='Data Sheet'!D30 -> 806.26 | E12: ='Data Sheet'!E30 -> 902.54 | F12: ='Data Sheet'!F30 -> 1301.08 | G12: ='Data Sheet'!G30 -> 1099.49 | H12: ='Data Sheet'!H30 -> 1492.55 | I12: ='Data Sheet'!I30 -> 2378.51 | ... K12: ='Data Sheet'!K30 -> 2708.02 | L12: =SUM(Quarters!H12:K12) -> 2707.17 | M12: =M10-M11*M10 -> 3612.9035 | N12: =N10-N11*N10 -> 3073.6027
A13: EPS | B13: =IF('Data Sheet'!B93>0,B12/'Data Sheet'!B93,0) -> 5.7032947 | C13: =IF('Data Sheet'!C93>0,C12/'Data Sheet'!C93,0) -> 7.6710463 | D13: =IF('Data Sheet'!D93>0,D12/'Data Sheet'!D93,0) -> 12.918763 | E13: =IF('Data Sheet'!E93>0,E12/'Data Sheet'!E93,0) -> 14.461465 | F13: =IF('Data Sheet'!F93>0,F12/'Data Sheet'!F93,0) -> 20.084594 | G13: =IF('Data Sheet'!G93>0,G12/'Data Sheet'!G93,0) -> 16.972677 | H13: =IF('Data Sheet'!H93>0,H12/'Data Sheet'!H93,0) -> 23.04029 | I13: =IF('Data Sheet'!I93>0,I12/'Data Sheet'!I93,0) -> 36.688416 | ... K13: =IF('Data Sheet'!K93>0,K12/'Data Sheet'!K93,0) -> 41.617028 | L13: =IF('Data Sheet'!$B6>0,'Profit & Loss'!L12/'Data Sheet'!$B6,0) -> 41.60185 | M13: =IF('Data Sheet'!$B6>0,'Profit & Loss'!M12/'Data Sheet'!$B6,0) -> 55.520514 | N13: =IF('Data Sheet'!$B6>0,'Profit & Loss'!N12/'Data Sheet'!$B6,0) -> 47.232925
A14: Price to earning | B14: =IF(B15>0,B15/B13,"") | C14: =IF(C15>0,C15/C13,"") -> 83.150326 | D14: =IF(D15>0,D15/D13,"") -> 102.54852 | E14: =IF(E15>0,E15/E13,"") -> 101.72552 | F14: =IF(F15>0,F15/F13,"") -> 108.91433 | G14: =IF(G15>0,G15/G13,"") -> 168.45015 | H14: =IF(H15>0,H15/H13,"") -> 173.75432 | I14: =IF(I15>0,I15/I13,"") -> 92.700923 | ... K14: =IF(K15>0,K15/K13,"") -> 98.113686 | L14: =IF(L13>0,L15/L13,0) -> 104.75976 | M14: =M25 -> 104.75976 | N14: =N25 -> 102.92169
A15: Price | B15: ='Data Sheet'!B90 -> 0 | C15: ='Data Sheet'!C90 -> 637.85 | D15: ='Data Sheet'!D90 -> 1324.8 | E15: ='Data Sheet'!E90 -> 1471.1 | F15: ='Data Sheet'!F90 -> 2187.5 | G15: ='Data Sheet'!G90 -> 2859.05 | H15: ='Data Sheet'!H90 -> 4003.35 | I15: ='Data Sheet'!I90 -> 3401.05 | ... K15: ='Data Sheet'!K90 -> 4083.2 | L15: ='Data Sheet'!B8 -> 4358.2 | M15: =M13*M14 -> 5816.316 | N15: =N13*N14 -> 4861.2927
A17: RATIOS:
A18: Dividend Payout | B18: =IF('Data Sheet'!B30>0, 'Data Sheet'!B31/'Data Sheet'!B30, 0) -> 0 | C18: =IF('Data Sheet'!C30>0, 'Data Sheet'!C31/'Data Sheet'!C30, 0) -> 0 | D18: =IF('Data Sheet'!D30>0, 'Data Sheet'!D31/'Data Sheet'!D30, 0) -> 0 | E18: =IF('Data Sheet'!E30>0, 'Data Sheet'!E31/'Data Sheet'!E30, 0) -> 0 | F18: =IF('Data Sheet'!F30>0, 'Data Sheet'!F31/'Data Sheet'!F30, 0) -> 0 | G18: =IF('Data Sheet'!G30>0, 'Data Sheet'!G31/'Data Sheet'!G30, 0) -> 0 | H18: =IF('Data Sheet'!H30>0, 'Data Sheet'!H31/'Data Sheet'!H30, 0) -> 0 | I18: =IF('Data Sheet'!I30>0, 'Data Sheet'!I31/'Data Sheet'!I30, 0) -> 0 | ... K18: =IF('Data Sheet'!K30>0, 'Data Sheet'!K31/'Data Sheet'!K30, 0) -> 0
A19: OPM | B19: =IF(B6>0,B6/B4,0) -> 0.077408968 | C19: =IF(C6>0,C6/C4,0) -> 0.081459442 | D19: =IF(D6>0,D6/D4,0) -> 0.089991486 | E19: =IF(E6>0,E6/E4,0) -> 0.081647048 | F19: =IF(F6>0,F6/F4,0) -> 0.085576714 | G19: =IF(G6>0,G6/G4,0) -> 0.072270458 | H19: =IF(H6>0,H6/H4,0) -> 0.080782806 | I19: =IF(I6>0,I6/I4,0) -> 0.084939481 | ... L19: =IF(L6>0,L6/L4,0) -> 0.074050656
G22: TRENDS: | H22: 10 YEARS | I22: 7 YEARS | J22: 5 YEARS | K22: 3 YEARS | L22: RECENT | M22: BEST | N22: WORST
G23: Sales Growth | H23: =IF(B4=0,"",POWER($K4/B4,1/9)-1) -> 0.23968498 | I23: =IF(D4=0,"",POWER($K4/D4,1/7)-1) -> 0.21675749 | J23: =IF(F4=0,"",POWER($K4/F4,1/5)-1) -> 0.19003592 | K23: =IF(H4=0,"",POWER($K4/H4, 1/3)-1) -> 0.24208171 | L23: =IF(ISERROR(MAX(IF(J4=0,"",(K4-J4)/J4),IF(K4=0,"",(L4-K4)/K4))),"",MAX(IF(J4=0,"",(K4-J4)/J4),IF(K4=0,"",(L4-K4)/K4))) -> 0.16872253 | M23: =MAX(K23:L23) -> 0.24208171 | N23: =MIN(H23:L23) -> 0.16872253
G24: OPM | H24: =IF(SUM(B4:$K$4)=0,"",SUMPRODUCT(B19:$K$19,B4:$K$4)/SUM(B4:$K$4)) -> 0.080535912 | I24: =IF(SUM(E4:$K$4)=0,"",SUMPRODUCT(E19:$K$19,E4:$K$4)/SUM(E4:$K$4)) -> 0.080036686 | J24: =IF(SUM(G4:$K$4)=0,"",SUMPRODUCT(G19:$K$19,G4:$K$4)/SUM(G4:$K$4)) -> 0.079219812 | K24: =IF(SUM(I4:$K$4)=0, "", SUMPRODUCT(I19:$K$19,I4:$K$4)/SUM(I4:$K$4)) -> 0.080000031 | L24: =L19 -> 0.074050656 | M24: =MAX(K24:L24) -> 0.080000031 | N24: =MIN(H24:L24) -> 0.074050656
G25: Price to Earning | H25: =IF(ISERROR(AVERAGEIF(B14:$L14,">0")),"",AVERAGEIF(B14:$L14,">0")) -> 115.02299 | I25: =IF(ISERROR(AVERAGEIF(E14:$L14,">0")),"",AVERAGEIF(E14:$L14,">0")) -> 120.56639 | J25: =IF(ISERROR(AVERAGEIF(G14:$L14,">0")),"",AVERAGEIF(G14:$L14,">0")) -> 125.64854 | K25: =IF(ISERROR(AVERAGEIF(I14:$L14,">0")),"",AVERAGEIF(I14:$L14,">0")) -> 102.92169 | L25: =L14 -> 104.75976 | M25: =MAX(K25:L25) -> 104.75976 | N25: =MIN(H25:L25) -> 102.92169

Sheet Quarters
A1: ='Profit & Loss'!A1 -> AVENUE SUPERMARTS LTD | E1: =UPDATE | J1: SCREENER.IN
A3: Narration | B3: ='Data Sheet'!B41 -> 45016 | C3: ='Data Sheet'!C41 -> 45107 | D3: ='Data Sheet'!D41 -> 45199 | E3: ='Data Sheet'!E41 -> 45291 | F3: ='Data Sheet'!F41 -> 45382 | G3: ='Data Sheet'!G41 -> 45473 | H3: ='Data Sheet'!H41 -> 45565 | I3: ='Data Sheet'!I41 -> 45657 | ... K3: ='Data Sheet'!K41 -> 45838
A4: Sales | B4: ='Data Sheet'!B42 -> 10594.11 | C4: ='Data Sheet'!C42 -> 11865.44 | D4: ='Data Sheet'!D42 -> 12624.37 | E4: ='Data Sheet'!E42 -> 13572.47 | F4: ='Data Sheet'!F42 -> 12726.55 | G4: ='Data Sheet'!G42 -> 14069.14 | H4: ='Data Sheet'!H42 -> 14444.5 | I4: ='Data Sheet'!I42 -> 15972.55 | ... K4: ='Data Sheet'!K42 -> 16359.7
A5: Expenses | B5: ='Data Sheet'!B43 -> 9822.6 | C5: ='Data Sheet'!C43 -> 10830.17 | D5: ='Data Sheet'!D43 -> 11619.4 | E5: ='Data Sheet'!E43 -> 12452.58 | F5: ='Data Sheet'!F43 -> 11782.91 | G5: ='Data Sheet'!G43 -> 12847.89 | H5: ='Data Sheet'!H43 -> 13350.73 | I5: ='Data Sheet'!I43 -> 14755.31 | ... K5: ='Data Sheet'!K43 -> 15060.66
A6: Operating Profit | B6: ='Data Sheet'!B50 -> 771.51 | C6: ='Data Sheet'!C50 -> 1035.27 | D6: ='Data Sheet'!D50 -> 1004.97 | E6: ='Data Sheet'!E50 -> 1119.89 | F6: ='Data Sheet'!F50 -> 943.64 | G6: ='Data Sheet'!G50 -> 1221.25 | H6: ='Data Sheet'!H50 -> 1093.77 | I6: ='Data Sheet'!I50 -> 1217.24 | ... K6: ='Data Sheet'!K50 -> 1299.04
A7: Other Income | B7: ='Data Sheet'!B44 -> 33.07 | C7: ='Data Sheet'!C44 -> 38.74 | D7: ='Data Sheet'!D44 -> 36.92 | E7: ='Data Sheet'!E44 -> 32.92 | F7: ='Data Sheet'!F44 -> 37.87 | G7: ='Data Sheet'!G44 -> 41.6 | H7: ='Data Sheet'!H44 -> 33.52 | I7: ='Data Sheet'!I44 -> 24.14 | ... K7: ='Data Sheet'!K44 -> 19.43
A8: Depreciation | B8: ='Data Sheet'!B45 -> 164.08 | C8: ='Data Sheet'!C45 -> 162.18 | D8: ='Data Sheet'!D45 -> 174.36 | E8: ='Data Sheet'!E45 -> 189.33 | F8: ='Data Sheet'!F45 -> 204.89 | G8: ='Data Sheet'!G45 -> 192.76 | H8: ='Data Sheet'!H45 -> 207.78 | I8: ='Data Sheet'!I45 -> 228.12 | ... K8: ='Data Sheet'!K45 -> 231.7
A9: Interest | B9: ='Data Sheet'!B46 -> 15.53 | C9: ='Data Sheet'!C46 -> 14.57 | D9: ='Data Sheet'!D46 -> 15.59 | E9: ='Data Sheet'!E46 -> 14.55 | F9: ='Data Sheet'!F46 -> 13.42 | G9: ='Data Sheet'!G46 -> 15.96 | H9: ='Data Sheet'!H46 -> 16.32 | I9: ='Data Sheet'!I46 -> 18.21 | ... K9: ='Data Sheet'!K46 -> 29.3
A10: Profit before tax | B10: ='Data Sheet'!B47 -> 624.97 | C10: ='Data Sheet'!C47 -> 897.26 | D10: ='Data Sheet'!D47 -> 851.94 | E10: ='Data Sheet'!E47 -> 948.93 | F10: ='Data Sheet'!F47 -> 763.2 | G10: ='Data Sheet'!G47 -> 1054.13 | H10: ='Data Sheet'!H47 -> 903.19 | I10: ='Data Sheet'!I47 -> 995.05 | ... K10: ='Data Sheet'!K47 -> 1057.47
A11: Tax | B11: ='Data Sheet'!B48 -> 164.87 | C11: ='Data Sheet'!C48 -> 238.55 | D11: ='Data Sheet'!D48 -> 228.59 | E11: ='Data Sheet'!E48 -> 258.52 | F11: ='Data Sheet'!F48 -> 200.06 | G11: ='Data Sheet'!G48 -> 280.45 | H11: ='Data Sheet'!H48 -> 243.75 | I11: ='Data Sheet'!I48 -> 271.51 | ... K11: ='Data Sheet'!K48 -> 284.66
A12: Net profit | B12: ='Data Sheet'!B49 -> 460.13 | C12: ='Data Sheet'!C49 -> 658.75 | D12: ='Data Sheet'!D49 -> 623.56 | E12: ='Data Sheet'!E49 -> 690.61 | F12: ='Data Sheet'!F49 -> 563.25 | G12: ='Data Sheet'!G49 -> 773.82 | H12: ='Data Sheet'!H49 -> 659.58 | I12: ='Data Sheet'!I49 -> 723.72 | ... K12: ='Data Sheet'!K49 -> 772.97
A14: OPM | B14: =IF(B4>0,B6/B4,"") -> 0.072824428 | C14: =IF(C4>0,C6/C4,"") -> 0.087250873 | D14: =IF(D4>0,D6/D4,"") -> 0.079605557 | E14: =IF(E4>0,E6/E4,"") -> 0.082511879 | F14: =IF(F4>0,F6/F4,"") -> 0.074147353 | G14: =IF(G4>0,G6/G4,"") -> 0.086803458 | H14: =IF(H4>0,H6/H4,"") -> 0.075722247 | I14: =IF(I4>0,I6/I4,"") -> 0.076208245 | ... K14: =IF(K4>0,K6/K4,"") -> 0.079404879

Sheet Balance Sheet
A1: ='Profit & Loss'!A1 -> AVENUE SUPERMARTS LTD | E1: =UPDATE | J1: SCREENER.IN
A3: Narration | B3: ='Data Sheet'!B56 -> 42460 | C3: ='Data Sheet'!C56 -> 42825 | D3: ='Data Sheet'!D56 -> 43190 | E3: ='Data Sheet'!E56 -> 43555 | F3: ='Data Sheet'!F56 -> 43921 | G3: ='Data Sheet'!G56 -> 44286 | H3: ='Data Sheet'!H56 -> 44651 | I3: ='Data Sheet'!I56 -> 45016 | ... K3: ='Data Sheet'!K56 -> 45747
A4: Equity Share Capital | B4: ='Data Sheet'!B57 -> 561.54 | C4: ='Data Sheet'!C57 -> 624.08 | D4: ='Data Sheet'!D57 -> 624.08 | E4: ='Data Sheet'!E57 -> 624.08 | F4: ='Data Sheet'!F57 -> 647.77 | G4: ='Data Sheet'!G57 -> 647.77 | H4: ='Data Sheet'!H57 -> 647.77 | I4: ='Data Sheet'!I57 -> 648.26 | ... K4: ='Data Sheet'!K57 -> 650.73
A5: Reserves | B5: ='Data Sheet'!B58 -> 958.9 | C5: ='Data Sheet'!C58 -> 3217.7 | D5: ='Data Sheet'!D58 -> 4044.97 | E5: ='Data Sheet'!E58 -> 4963.37 | F5: ='Data Sheet'!F58 -> 10431.97 | G5: ='Data Sheet'!G58 -> 11535.94 | H5: ='Data Sheet'!H58 -> 13029.87 | I5: ='Data Sheet'!I58 -> 15430.44 | ... K5: ='Data Sheet'!K58 -> 20777.02
A6: Borrowings | B6: ='Data Sheet'!B59 -> 1192.34 | C6: ='Data Sheet'!C59 -> 1497.32 | D6: ='Data Sheet'!D59 -> 439.25 | E6: ='Data Sheet'!E59 -> 700.15 | F6: ='Data Sheet'!F59 -> 333.19 | G6: ='Data Sheet'!G59 -> 392.71 | H6: ='Data Sheet'!H59 -> 646.94 | I6: ='Data Sheet'!I59 -> 642.98 | ... K6: ='Data Sheet'!K59 -> 819.62
A7: Other Liabilities | B7: ='Data Sheet'!B60 -> 388.78 | C7: ='Data Sheet'!C60 -> 480.18 | D7: ='Data Sheet'!D60 -> 539.92 | E7: ='Data Sheet'!E60 -> 717.9 | F7: ='Data Sheet'!F60 -> 663.23 | G7: ='Data Sheet'!G60 -> 1078.63 | H7: ='Data Sheet'!H60 -> 1146.4 | I7: ='Data Sheet'!I60 -> 1382.84 | ... K7: ='Data Sheet'!K60 -> 2065.41
A8: Total | B8: ='Data Sheet'!B61 -> 3101.56 | C8: ='Data Sheet'!C61 -> 5819.28 | D8: ='Data Sheet'!D61 -> 5648.22 | E8: ='Data Sheet'!E61 -> 7005.5 | F8: ='Data Sheet'!F61 -> 12076.16 | G8: ='Data Sheet'!G61 -> 13655.05 | H8: ='Data Sheet'!H61 -> 15470.98 | I8: ='Data Sheet'!I61 -> 18104.52 | ... K8: ='Data Sheet'!K61 -> 24312.78
A10: Net Block | B10: ='Data Sheet'!B62 -> 2093.52 | C10: ='Data Sheet'!C62 -> 2577.75 | D10: ='Data Sheet'!D62 -> 3399.97 | E10: ='Data Sheet'!E62 -> 4400.37 | F10: ='Data Sheet'!F62 -> 5948.03 | G10: ='Data Sheet'!G62 -> 7008.8 | H10: ='Data Sheet'!H62 -> 9260.02 | I10: ='Data Sheet'!I62 -> 11340.48 | ... K10: ='Data Sheet'!K62 -> 16206.46
A11: Capital Work in Progress | B11: ='Data Sheet'!B63 -> 81.69 | C11: ='Data Sheet'!C63 -> 152.89 | D11: ='Data Sheet'!D63 -> 147.07 | E11: ='Data Sheet'!E63 -> 376.84 | F11: ='Data Sheet'!F63 -> 364.4 | G11: ='Data Sheet'!G63 -> 1019.59 | H11: ='Data Sheet'!H63 -> 1129.34 | I11: ='Data Sheet'!I63 -> 829.16 | ... K11: ='Data Sheet'!K63 -> 1099.35
A12: Investments | B12: ='Data Sheet'!B64 -> 29.33 | C12: ='Data Sheet'!C64 -> 25.69 | D12: ='Data Sheet'!D64 -> 68.18 | E12: ='Data Sheet'!E64 -> 16.53 | F12: ='Data Sheet'!F64 -> 14.68 | G12: ='Data Sheet'!G64 -> 2.95 | H12: ='Data Sheet'!H64 -> 5.94 | I12: ='Data Sheet'!I64 -> 202.2 | ... K12: ='Data Sheet'!K64 -> 3.26
A13: Other Assets | B13: ='Data Sheet'!B65 -> 897.02 | C13: ='Data Sheet'!C65 -> 3062.95 | D13: ='Data Sheet'!D65 -> 2033 | E13: ='Data Sheet'!E65 -> 2211.76 | F13: ='Data Sheet'!F65 -> 5749.05 | G13: ='Data Sheet'!G65 -> 5623.71 | H13: ='Data Sheet'!H65 -> 5075.68 | I13: ='Data Sheet'!I65 -> 5732.68 | ... K13: ='Data Sheet'!K65 -> 7003.71
A14: Total | B14: ='Data Sheet'!B66 -> 3101.56 | C14: ='Data Sheet'!C66 -> 5819.28 | D14: ='Data Sheet'!D66 -> 5648.22 | E14: ='Data Sheet'!E66 -> 7005.5 | F14: ='Data Sheet'!F66 -> 12076.16 | G14: ='Data Sheet'!G66 -> 13655.05 | H14: ='Data Sheet'!H66 -> 15470.98 | I14: ='Data Sheet'!I66 -> 18104.52 | ... K14: ='Data Sheet'!K66 -> 24312.78
A16: Working Capital | B16: =B13-B7 -> 508.24 | C16: =C13-C7 -> 2582.77 | D16: =D13-D7 -> 1493.08 | E16: =E13-E7 -> 1493.86 | F16: =F13-F7 -> 5085.82 | G16: =G13-G7 -> 4545.08 | H16: =H13-H7 -> 3929.28 | I16: =I13-I7 -> 4349.84 | ... K16: =K13-K7 -> 4938.3
A17: Debtors | B17: ='Data Sheet'!B67 -> 8.42 | C17: ='Data Sheet'!C67 -> 21 | D17: ='Data Sheet'!D67 -> 33.52 | E17: ='Data Sheet'!E67 -> 64.37 | F17: ='Data Sheet'!F67 -> 19.55 | G17: ='Data Sheet'!G67 -> 43.58 | H17: ='Data Sheet'!H67 -> 66.89 | I17: ='Data Sheet'!I67 -> 62.16 | ... K17: ='Data Sheet'!K67 -> 153.79
A18: Inventory | B18: ='Data Sheet'!B68 -> 671.69 | C18: ='Data Sheet'!C68 -> 947.9 | D18: ='Data Sheet'!D68 -> 1163.45 | E18: ='Data Sheet'!E68 -> 1608.65 | F18: ='Data Sheet'!F68 -> 1947.4 | G18: ='Data Sheet'!G68 -> 2248.28 | H18: ='Data Sheet'!H68 -> 2742.66 | I18: ='Data Sheet'!I68 -> 3243.48 | ... K18: ='Data Sheet'!K68 -> 5044.37
A20: Debtor Days | B20: =IF('Profit & Loss'!B4>0,'Balance Sheet'!B17/('Profit & Loss'!B4/365),0) -> 0.35803657 | C20: =IF('Profit & Loss'!C4>0,'Balance Sheet'!C17/('Profit & Loss'!C4/365),0) -> 0.64424216 | D20: =IF('Profit & Loss'!D4>0,'Balance Sheet'!D17/('Profit & Loss'!D4/365),0) -> 0.81385201 | E20: =IF('Profit & Loss'!E4>0,'Balance Sheet'!E17/('Profit & Loss'!E4/365),0) -> 1.1744871 | F20: =IF('Profit & Loss'!F4>0,'Balance Sheet'!F17/('Profit & Loss'!F4/365),0) -> 0.28691969 | G20: =IF('Profit & Loss'!G4>0,'Balance Sheet'!G17/('Profit & Loss'!G4/365),0) -> 0.65885186 | H20: =IF('Profit & Loss'!H4>0,'Balance Sheet'!H17/('Profit & Loss'!H4/365),0) -> 0.78817914 | I20: =IF('Profit & Loss'!I4>0,'Balance Sheet'!I17/('Profit & Loss'!I4/365),0) -> 0.52961328 | ... K20: =IF('Profit & Loss'!K4>0,'Balance Sheet'!K17/('Profit & Loss'!K4/365),0) -> 0.94567375
A21: Inventory Turnover | B21: =IF('Balance Sheet'!B18>0,'Profit & Loss'!B4/'Balance Sheet'!B18,0) -> 12.779348 | C21: =IF('Balance Sheet'!C18>0,'Profit & Loss'!C4/'Balance Sheet'!C18,0) -> 12.55164 | D21: =IF('Balance Sheet'!D18>0,'Profit & Loss'!D4/'Balance Sheet'!D18,0) -> 12.921226 | E21: =IF('Balance Sheet'!E18>0,'Profit & Loss'!E4/'Balance Sheet'!E18,0) -> 12.435595 | F21: =IF('Balance Sheet'!F18>0,'Profit & Loss'!F4/'Balance Sheet'!F18,0) -> 12.770977 | G21: =IF('Balance Sheet'!G18>0,'Profit & Loss'!G4/'Balance Sheet'!G18,0) -> 10.738458 | H21: =IF('Balance Sheet'!H18>0,'Profit & Loss'!H4/'Balance Sheet'!H18,0) -> 11.294244 | I21: =IF('Balance Sheet'!I18>0,'Profit & Loss'!I4/'Balance Sheet'!I18,0) -> 13.2079 | ... K21: =IF('Balance Sheet'!K18>0,'Profit & Loss'!K4/'Balance Sheet'!K18,0) -> 11.767188
A23: Return on Equity | B23: =IF(SUM('Balance Sheet'!B4:B5)>0,'Profit & Loss'!B12/SUM('Balance Sheet'!B4:B5),"") -> 0.21062324 | C23: =IF(SUM('Balance Sheet'!C4:C5)>0,'Profit & Loss'!C12/SUM('Balance Sheet'!C4:C5),"") -> 0.12461671 | D23: =IF(SUM('Balance Sheet'!D4:D5)>0,'Profit & Loss'!D12/SUM('Balance Sheet'!D4:D5),"") -> 0.17268181 | E23: =IF(SUM('Balance Sheet'!E4:E5)>0,'Profit & Loss'!E12/SUM('Balance Sheet'!E4:E5),"") -> 0.16152986 | F23: =IF(SUM('Balance Sheet'!F4:F5)>0,'Profit & Loss'!F12/SUM('Balance Sheet'!F4:F5),"") -> 0.11742875 | G23: =IF(SUM('Balance Sheet'!G4:G5)>0,'Profit & Loss'!G12/SUM('Balance Sheet'!G4:G5),"") -> 0.090242627 | H23: =IF(SUM('Balance Sheet'!H4:H5)>0,'Profit & Loss'!H12/SUM('Balance Sheet'!H4:H5),"") -> 0.10912336 | I23: =IF(SUM('Balance Sheet'!I4:I5)>0,'Profit & Loss'!I12/SUM('Balance Sheet'!I4:I5),"") -> 0.14792925 | ... K23: =IF(SUM('Balance Sheet'!K4:K5)>0,'Profit & Loss'!K12/SUM('Balance Sheet'!K4:K5),"") -> 0.12637911
A24: Return on Capital Emp | C24: =IF((B4+B5+B6+C4+C5+C6)>0,('Profit & Loss'!C10+'Profit & Loss'!C9)*2/(B4+B5+B6+C4+C5+C6),"") -> 0.21586511 | D24: =IF((C4+C5+C6+D4+D5+D6)>0,('Profit & Loss'!D10+'Profit & Loss'!D9)*2/(C4+C5+C6+D4+D5+D6),"") -> 0.24534525 | E24: =IF((D4+D5+D6+E4+E5+E6)>0,('Profit & Loss'!E10+'Profit & Loss'!E9)*2/(D4+D5+D6+E4+E5+E6),"") -> 0.25783835 | F24: =IF((E4+E5+E6+F4+F5+F6)>0,('Profit & Loss'!F10+'Profit & Loss'!F9)*2/(E4+E5+E6+F4+F5+F6),"") -> 0.20495319 | G24: =IF((F4+F5+F6+G4+G5+G6)>0,('Profit & Loss'!G10+'Profit & Loss'!G9)*2/(F4+F5+F6+G4+G5+G6),"") -> 0.12714809 | H24: =IF((G4+G5+G6+H4+H5+H6)>0,('Profit & Loss'!H10+'Profit & Loss'!H9)*2/(G4+G5+G6+H4+H5+H6),"") -> 0.15745957 | I24: =IF((H4+H5+H6+I4+I5+I6)>0,('Profit & Loss'!I10+'Profit & Loss'!I9)*2/(H4+H5+H6+I4+I5+I6),"") -> 0.20147354 | J24: =IF((I4+I5+I6+J4+J5+J6)>0,('Profit & Loss'!J10+'Profit & Loss'!J9)*2/(I4+I5+I6+J4+J5+J6),"") -> 0.19546225 | K24: =IF((J4+J5+J6+K4+K5+K6)>0,('Profit & Loss'!K10+'Profit & Loss'!K9)*2/(J4+J5+J6+K4+K5+K6),"") -> 0.18018097

Sheet Cash Flow
A1: ='Balance Sheet'!A1 -> AVENUE SUPERMARTS LTD | E1: =UPDATE | J1: SCREENER.IN
A3: Narration | B3: ='Data Sheet'!B81 -> 42460 | C3: ='Data Sheet'!C81 -> 42825 | D3: ='Data Sheet'!D81 -> 43190 | E3: ='Data Sheet'!E81 -> 43555 | F3: ='Data Sheet'!F81 -> 43921 | G3: ='Data Sheet'!G81 -> 44286 | H3: ='Data Sheet'!H81 -> 44651 | I3: ='Data Sheet'!I81 -> 45016 | ... K3: ='Data Sheet'!K81 -> 45747
A4: Cash from Operating Activity | B4: ='Data Sheet'!B82 -> 433.47 | C4: ='Data Sheet'!C82 -> 455.28 | D4: ='Data Sheet'!D82 -> 729.99 | E4: ='Data Sheet'!E82 -> 806.84 | F4: ='Data Sheet'!F82 -> 1280.14 | G4: ='Data Sheet'!G82 -> 1375.14 | H4: ='Data Sheet'!H82 -> 1372.35 | I4: ='Data Sheet'!I82 -> 2630.27 | ... K4: ='Data Sheet'!K82 -> 2462.97
A5: Cash from Investing Activity | B5: ='Data Sheet'!B83 -> -632.89 | C5: ='Data Sheet'!C83 -> -2481.61 | D5: ='Data Sheet'!D83 -> 463.55 | E5: ='Data Sheet'!E83 -> -958.37 | F5: ='Data Sheet'!F83 -> -4656.56 | G5: ='Data Sheet'!G83 -> -1110 | H5: ='Data Sheet'!H83 -> -1289.49 | I5: ='Data Sheet'!I83 -> -2313.1 | ... K5: ='Data Sheet'!K83 -> -2185.31
A6: Cash from Financing Activity | B6: ='Data Sheet'!B84 -> 196.44 | C6: ='Data Sheet'!C84 -> 2025.26 | D6: ='Data Sheet'!D84 -> -1159.06 | E6: ='Data Sheet'!E84 -> 208.98 | F6: ='Data Sheet'!F84 -> 3357.42 | G6: ='Data Sheet'!G84 -> -179.5 | H6: ='Data Sheet'!H84 -> -179.24 | I6: ='Data Sheet'!I84 -> -205.14 | ... K6: ='Data Sheet'!K84 -> -259.3
A7: Net Cash Flow | B7: ='Data Sheet'!B85 -> -2.98 | C7: ='Data Sheet'!C85 -> -1.07 | D7: ='Data Sheet'!D85 -> 34.48 | E7: ='Data Sheet'!E85 -> 57.45 | F7: ='Data Sheet'!F85 -> -19 | G7: ='Data Sheet'!G85 -> 85.64 | H7: ='Data Sheet'!H85 -> -96.38 | I7: ='Data Sheet'!I85 -> 112.03 | ... K7: ='Data Sheet'!K85 -> 18.36

Sheet Data Sheet
A1: COMPANY NAME | B1: AVENUE SUPERMARTS LTD | E1: =IF(B2<>B3, "A NEW VERSION OF THE WORKSHEET IS AVAILABLE", "")
A2: LATEST VERSION | B2: 2.1 | E2: PLEASE DO NOT MAKE ANY CHANGES TO THIS SHEET
A3: CURRENT VERSION | B3: 2.1
A5: META
A6: Number of shares | B6: =IF(B9>0, B9/B8, 0) -> 65.073308
A7: Face Value | B7: 10
A8: Current Price | B8: 4358.2
A9: Market Capitalization | B9: 283602.49
A15: PROFIT & LOSS
A16: Report Date | B16: 42460 | C16: 42825 | D16: 43190 | E16: 43555 | F16: 43921 | G16: 44286 | H16: 44651 | I16: 45016 | J16: 45382 | K16: 45747
A17: Sales | B17: 8583.76 | C17: 11897.7 | D17: 15033.2 | E17: 20004.52 | F17: 24870.2 | G17: 24143.06 | H17: 30976.27 | I17: 42839.56 | J17: 50788.83 | K17: 59358.05
A18: Raw Material Cost | B18: 7435.62 | C18: 10357.25 | D18: 12846.95 | E18: 17445.49 | F18: 21441.68 | G18: 20855.56 | H18: 26891.77 | I18: 36884.77 | J18: 43958.31 | K18: 51668.76
A19: Change in Inventory | B19: 132.08 | C19: 276.22 | D19: 211.31 | E19: 444.65 | F19: 338.75 | G19: 300.88 | H19: 494.38 | I19: 500.82 | J19: 683.77 | K19: 1117.06
A20: Power and Fuel | B20: 79.24 | C20: 99.41 | D20: 121.26 | E20: 152.8 | F20: 188.24 | G20: 174.2 | H20: 207.86 | I20: 314.62 | J20: 376.59 | K20: 447.75
A21: Other Mfr. Exp | B21: 241.36 | C21: 332.9 | D21: 373.72 | E21: 499.72 | F21: 645.96 | G21: 746.43 | H21: 805.85 | I21: 1116.56 | J21: 1323.43 | K21: 1751.85
A22: Employee Cost | B22: 149.04 | C22: 192.67 | D22: 283.14 | E22: 356.17 | F22: 457.14 | G22: 537.58 | H22: 617.36 | I22: 748.16 | J22: 907.82 | K22: 1167.47
A23: Selling and admin | B23: 647.37 | C23: 71.24 | D23: 96 | E23: 135.84 | F23: 119.23 | G23: 108.69 | H23: 143.41 | I23: 212.04 | J23: 274.43 | K23: 312.48
A24: Other Expenses | B24: -501.25 | C24: 151.27 | D24: 170.58 | E24: 225.84 | F24: 228.39 | G24: 276.65 | H24: 302.05 | I24: 425.46 | J24: 526.38 | K24: 632.29
A25: Other Income | B25: 17.02 | C25: 27.7 | D25: 87.75 | E25: 48.33 | F25: 59.99 | G25: 194.43 | H25: 113.64 | I25: 127.6 | J25: 144.58 | K25: 117.13
A26: Depreciation | B26: 98.43 | C26: 127.82 | D26: 159 | E26: 212.49 | F26: 374.41 | G26: 414.16 | H26: 498.08 | I26: 638.87 | J26: 730.76 | K26: 869.52
A27: Interest | B27: 91.34 | C27: 121.98 | D27: 59.54 | E27: 47.21 | F27: 69.12 | G27: 41.65 | H27: 53.79 | I27: 67.41 | J27: 58.13 | K27: 69.45
... A30: Net profit | B30: 320.24 | C30: 478.75 | D30: 806.26 | E30: 902.54 | F30: 1301.08 | G30: 1099.49 | H30: 1492.55 | I30: 2378.51 | J30: 2536.17 | K30: 2708.02
A31: Dividend Amount
A32: EBITDA | B32: =B30+B27+B29+B26 -> 681.48 | C32: =C30+C27+C29+C26 -> 996.83 | D32: =D30+D27+D29+D26 -> 1440.59 | E32: =E30+E27+E29+E26 -> 1681.72 | F32: =F30+F27+F29+F26 -> 2188.4 | G32: =G30+G27+G29+G26 -> 1939.32 | H32: =H30+H27+H29+H26 -> 2616.14 | I32: =I30+I27+I29+I26 -> 3766.54 | ... K32: =K30+K27+K29+K26 -> 4612.21
A40: Quarters
A41: Report Date | B41: 45016 | C41: 45107 | D41: 45199 | E41: 45291 | F41: 45382 | G41: 45473 | H41: 45565 | I41: 45657 | J41: 45747 | K41: 45838
A42: Sales | B42: 10594.11 | C42: 11865.44 | D42: 12624.37 | E42: 13572.47 | F42: 12726.55 | G42: 14069.14 | H42: 14444.5 | I42: 15972.55 | J42: 14871.86 | K42: 16359.7
A43: Expenses | B43: 9822.6 | C43: 10830.17 | D43: 11619.4 | E43: 12452.58 | F43: 11782.91 | G43: 12847.89 | H43: 13350.73 | I43: 14755.31 | J43: 13916.79 | K43: 15060.66
A44: Other Income | B44: 33.07 | C44: 38.74 | D44: 36.92 | E44: 32.92 | F44: 37.87 | G44: 41.6 | H44: 33.52 | I44: 24.14 | J44: 25.05 | K44: 19.43
A45: Depreciation | B45: 164.08 | C45: 162.18 | D45: 174.36 | E45: 189.33 | F45: 204.89 | G45: 192.76 | H45: 207.78 | I45: 228.12 | J45: 240.86 | K45: 231.7
A46: Interest | B46: 15.53 | C46: 14.57 | D46: 15.59 | E46: 14.55 | F46: 13.42 | G46: 15.96 | H46: 16.32 | I46: 18.21 | J46: 18.96 | K46: 29.3
A47: Profit before tax | B47: 624.97 | C47: 897.26 | D47: 851.94 | E47: 948.93 | F47: 763.2 | G47: 1054.13 | H47: 903.19 | I47: 995.05 | J47: 720.3 | K47: 1057.47
A48: Tax | B48: 164.87 | C48: 238.55 | D48: 228.59 | E48: 258.52 | F48: 200.06 | G48: 280.45 | H48: 243.75 | I48: 271.51 | J48: 169.51 | K48: 284.66
A49: Net profit | B49: 460.13 | C49: 658.75 | D49: 623.56 | E49: 690.61 | F49: 563.25 | G49: 773.82 | H49: 659.58 | I49: 723.72 | J49: 550.9 | K49: 772.97
A50: Operating Profit | B50: 771.51 | C50: 1035.27 | D50: 1004.97 | E50: 1119.89 | F50: 943.64 | G50: 1221.25 | H50: 1093.77 | I50: 1217.24 | J50: 955.07 | K50: 1299.04
A55: BALANCE SHEET
A56: Report Date | B56: 42460 | C56: 42825 | D56: 43190 | E56: 43555 | F56: 43921 | G56: 44286 | H56: 44651 | I56: 45016 | J56: 45382 | K56: 45747
A57: Equity Share Capital | B57: 561.54 | C57: 624.08 | D57: 624.08 | E57: 624.08 | F57: 647.77 | G57: 647.77 | H57: 647.77 | I57: 648.26 | J57: 650.73 | K57: 650.73
A58: Reserves | B58: 958.9 | C58: 3217.7 | D58: 4044.97 | E58: 4963.37 | F58: 10431.97 | G58: 11535.94 | H58: 13029.87 | I58: 15430.44 | J58: 18047.09 | K58: 20777.02
A59: Borrowings | B59: 1192.34 | C59: 1497.32 | D59: 439.25 | E59: 700.15 | F59: 333.19 | G59: 392.71 | H59: 646.94 | I59: 642.98 | J59: 592.16 | K59: 819.62
...

Sheet HistoricaIFS
B2: ="Historial Financial Statement - "&'Data Sheet'!B1 -> Historial Financial Statement - AVENUE SUPERMARTS LTD
B3: Years | C3: ='Data Sheet'!B16 -> 42460 | D3: ='Data Sheet'!C16 -> 42825 | E3: ='Data Sheet'!D16 -> 43190 | F3: ='Data Sheet'!E16 -> 43555 | G3: ='Data Sheet'!F16 -> 43921 | H3: ='Data Sheet'!G16 -> 44286 | I3: ='Data Sheet'!H16 -> 44651 | J3: ='Data Sheet'!I16 -> 45016 | ... L3: ='Data Sheet'!K16 -> 45747 | M3: LTM
A4: # | B4: Income Statement
B5: Sales | C5: =IFERROR('Data Sheet'!B17,0) -> 8583.76 | D5: =IFERROR('Data Sheet'!C17,0) -> 11897.7 | E5: =IFERROR('Data Sheet'!D17,0) -> 15033.2 | F5: =IFERROR('Data Sheet'!E17,0) -> 20004.52 | G5: =IFERROR('Data Sheet'!F17,0) -> 24870.2 | H5: =IFERROR('Data Sheet'!G17,0) -> 24143.06 | I5: =IFERROR('Data Sheet'!H17,0) -> 30976.27 | J5: =IFERROR('Data Sheet'!I17,0) -> 42839.56 | ... L5: =IFERROR('Data Sheet'!K17,0) -> 59358.05 | M5: =IFERROR(SUM('Data Sheet'!H42:K42),0) -> 61648.61
B6: Sales Growth | C6: - | D6: =D5/C5-1 -> 0.38607091 | E6: =E5/D5-1 -> 0.26353833 | F6: =F5/E5-1 -> 0.33068941 | G6: =G5/F5-1 -> 0.24322903 | H6: =H5/G5-1 -> -0.029237401 | I6: =I5/H5-1 -> 0.28302999 | J6: =J5/I5-1 -> 0.38297994 | K6: =K5/J5-1 -> 0.1855591 | ... M6: =M5/L5-1 -> 0.038588869
B8: COGS | C8: =IFERROR(SUM('Data Sheet'!B18,'Data Sheet'!B20:B22)-1*'Data Sheet'!B19,0) -> 7773.18 | D8: =IFERROR(SUM('Data Sheet'!C18,'Data Sheet'!C20:C22)-1*'Data Sheet'!C19,0) -> 10706.01 | E8: =IFERROR(SUM('Data Sheet'!D18,'Data Sheet'!D20:D22)-1*'Data Sheet'!D19,0) -> 13413.76 | F8: =IFERROR(SUM('Data Sheet'!E18,'Data Sheet'!E20:E22)-1*'Data Sheet'!E19,0) -> 18009.53 | G8: =IFERROR(SUM('Data Sheet'!F18,'Data Sheet'!F20:F22)-1*'Data Sheet'!F19,0) -> 22394.27 | H8: =IFERROR(SUM('Data Sheet'!G18,'Data Sheet'!G20:G22)-1*'Data Sheet'!G19,0) -> 22012.89 | I8: =IFERROR(SUM('Data Sheet'!H18,'Data Sheet'!H20:H22)-1*'Data Sheet'!H19,0) -> 28028.46 | J8: =IFERROR(SUM('Data Sheet'!I18,'Data Sheet'!I20:I22)-1*'Data Sheet'!I19,0) -> 38563.29 | ... L8: =IFERROR(SUM('Data Sheet'!K18,'Data Sheet'!K20:K22)-1*'Data Sheet'!K19,0) -> 53918.77 | M8: =IFERROR(SUM('Data Sheet'!H43:K43),0) -> 57083.49
B9: Gross Margine(COGS % Sales) | C9: =C8/C5 -> 0.90556819 | D9: =D8/D5 -> 0.89983862 | E9: =E8/E5 -> 0.89227576 | F9: =F8/F5 -> 0.90027304 | G9: =G8/G5 -> 0.90044592 | H9: =H8/H5 -> 0.91176885 | I9: =I8/I5 -> 0.90483651 | J9: =J8/J5 -> 0.90017941 | ... M9: =M8/M5 -> 0.92594934
B11: Gross Profit | C11: =C5-C8 -> 810.58 | D11: =D5-D8 -> 1191.69 | E11: =E5-E8 -> 1619.44 | F11: =F5-F8 -> 1994.99 | G11: =G5-G8 -> 2475.93 | H11: =H5-H8 -> 2130.17 | I11: =I5-I8 -> 2947.81 | J11: =J5-J8 -> 4276.27 | ... M11: =M5-M8 -> 4565.12
B12: Gross Profit % Sales | C12: =C11/C5 -> 0.094431811 | D12: =D11/D5 -> 0.10016138 | E12: =E11/E5 -> 0.10772424 | F12: =F11/F5 -> 0.099726962 | G12: =G11/G5 -> 0.099554085 | H12: =H11/H5 -> 0.088231152 | I12: =I11/I5 -> 0.095163491 | J12: =J11/J5 -> 0.099820586 | ... M12: =M11/M5 -> 0.074050656
B14: Selling & Gernal Expenses | C14: =IFERROR(SUM('Data Sheet'!B23:B24),0) -> 146.12 | D14: =IFERROR(SUM('Data Sheet'!C23:C24),0) -> 222.51 | E14: =IFERROR(SUM('Data Sheet'!D23:D24),0) -> 266.58 | F14: =IFERROR(SUM('Data Sheet'!E23:E24),0) -> 361.68 | G14: =IFERROR(SUM('Data Sheet'!F23:F24),0) -> 347.62 | H14: =IFERROR(SUM('Data Sheet'!G23:G24),0) -> 385.34 | I14: =IFERROR(SUM('Data Sheet'!H23:H24),0) -> 445.46 | J14: =IFERROR(SUM('Data Sheet'!I23:I24),0) -> 637.5 | ... L14: =IFERROR(SUM('Data Sheet'!K23:K24),0) -> 944.77
B15: S & G Exp % Sales | C15: =C14/C5 -> 0.017022843 | D15: =D14/D5 -> 0.018701934 | E15: =E14/E5 -> 0.017732752 | F15: =F14/F5 -> 0.018079914 | G15: =G14/G5 -> 0.013977371 | H15: =H14/H5 -> 0.015960694 | I15: =I14/I5 -> 0.014380686 | J15: =J14/J5 -> 0.014881105 | ... M15: =M14/M5 -> 0
P16: =D17-D23 -> 841.36
B17: EBITDA | C17: =C11-C14 -> 664.46 | D17: =D11-D14 -> 969.18 | E17: =E11-E14 -> 1352.86 | F17: =F11-F14 -> 1633.31 | G17: =G11-G14 -> 2128.31 | H17: =H11-H14 -> 1744.83 | I17: =I11-I14 -> 2502.35 | J17: =J11-J14 -> 3638.77 | ... M17: =M11-M14 -> 4565.12
B18: EBITDA % Sales | C18: =C17/C5 -> 0.077408968 | D18: =D17/D5 -> 0.081459442 | E18: =E17/E5 -> 0.089991486 | F18: =F17/F5 -> 0.081647048 | G18: =G17/G5 -> 0.085576714 | H18: =H17/H5 -> 0.072270458 | I18: =I17/I5 -> 0.080782806 | J18: =J17/J5 -> 0.084939481 | ... M18: =M17/M5 -> 0.074050656
B20: Interest | C20: ='Data Sheet'!B27 -> 91.34 | D20: ='Data Sheet'!C27 -> 121.98 | E20: ='Data Sheet'!D27 -> 59.54 | F20: ='Data Sheet'!E27 -> 47.21 | G20: ='Data Sheet'!F27 -> 69.12 | H20: ='Data Sheet'!G27 -> 41.65 | I20: ='Data Sheet'!H27 -> 53.79 | J20: ='Data Sheet'!I27 -> 67.41 | ... L20: ='Data Sheet'!K27 -> 69.45 | M20: =IFERROR(SUM('Data Sheet'!H46:K46),0) -> 82.79
B21: Interest % Sales | C21: =C20/C5 -> 0.010641024 | D21: =D20/D5 -> 0.010252402 | E21: =E20/E5 -> 0.0039605673 | F21: =F20/F5 -> 0.0023599666 | G21: =G20/G5 -> 0.0027792298 | H21: =H20/H5 -> 0.0017251334 | I21: =I20/I5 -> 0.0017364905 | J21: =J20/J5 -> 0.0015735456 | ... M21: =M20/M5 -> 0.0013429338
B23: Deprisiation | C23: =IFERROR('Data Sheet'!B26,0) -> 98.43 | D23: =IFERROR('Data Sheet'!C26,0) -> 127.82 | E23: =IFERROR('Data Sheet'!D26,0) -> 159 | F23: =IFERROR('Data Sheet'!E26,0) -> 212.49 | G23: =IFERROR('Data Sheet'!F26,0) -> 374.41 | H23: =IFERROR('Data Sheet'!G26,0) -> 414.16 | I23: =IFERROR('Data Sheet'!H26,0) -> 498.08 | J23: =IFERROR('Data Sheet'!I26,0) -> 638.87 | ... L23: =IFERROR('Data Sheet'!K26,0) -> 869.52 | M23: =IFERROR(SUM('Data Sheet'!H45:K45),0) -> 908.46
B24: Deprisiation % Sales | C24: =C23/C5 -> 0.011467003 | D24: =D23/D5 -> 0.010743253 | E24: =E23/E5 -> 0.01057659 | F24: =F23/F5 -> 0.010622099 | G24: =G23/G5 -> 0.015054563 | H24: =H23/H5 -> 0.017154412 | I24: =I23/I5 -> 0.016079405 | J24: =J23/J5 -> 0.014913085 | ... M24: =M23/M5 -> 0.014736099
B26: EBT | C26: =IFERROR(C17-SUM(C20,C23),0) -> 474.69 | D26: =IFERROR(D17-SUM(D20,D23),0) -> 719.38 | E26: =IFERROR(E17-SUM(E20,E23),0) -> 1134.32 | F26: =IFERROR(F17-SUM(F20,F23),0) -> 1373.61 | G26: =IFERROR(G17-SUM(G20,G23),0) -> 1684.78 | H26: =IFERROR(H17-SUM(H20,H23),0) -> 1289.02 | I26: =IFERROR(I17-SUM(I20,I23),0) -> 1950.48 | J26: =IFERROR(J17-SUM(J20,J23),0) -> 2932.49 | ... M26: =IFERROR(M17-SUM(M20,M23),0) -> 3573.87 | O26: =L26-K26-1 -> 237.79
B27: EBT % Sales | C27: =C26/C5 -> 0.05530094 | D27: =D26/D5 -> 0.060463787 | E27: =E26/E5 -> 0.075454328 | F27: =F26/F5 -> 0.068664982 | G27: =G26/G5 -> 0.067742921 | H27: =H26/H5 -> 0.053390912 | I27: =I26/I5 -> 0.06296691 | J27: =J26/J5 -> 0.068452851 | ... M27: =M26/M5 -> 0.057971623
B29: TAX | C29: ='Data Sheet'!B29 -> 171.47 | D29: ='Data Sheet'!C29 -> 268.28 | E29: ='Data Sheet'!D29 -> 415.79 | F29: ='Data Sheet'!E29 -> 519.48 | G29: ='Data Sheet'!F29 -> 443.79 | H29: ='Data Sheet'!G29 -> 384.02 | I29: ='Data Sheet'!H29 -> 571.72 | J29: ='Data Sheet'!I29 -> 681.75 | ... L29: ='Data Sheet'!K29 -> 965.22 | M29: =IFERROR(SUM('Data Sheet'!H48:K48),0) -> 969.43
B30: TAX % Sales | C30: =C29/C5 -> 0.019976094 | D30: =D29/D5 -> 0.022548896 | E30: =E29/E5 -> 0.027658117 | F30: =F29/F5 -> 0.025968131 | G30: =G29/G5 -> 0.017844247 | H30: =H29/H5 -> 0.01590602 | I30: =I29/I5 -> 0.018456709 | J30: =J29/J5 -> 0.015914029 | ... M30: =M29/M5 -> 0.015725091
B32: Net Profit | C32: ='Data Sheet'!B30 -> 320.24 | D32: ='Data Sheet'!C30 -> 478.75 | E32: ='Data Sheet'!D30 -> 806.26 | F32: ='Data Sheet'!E30 -> 902.54 | G32: ='Data Sheet'!F30 -> 1301.08 | H32: ='Data Sheet'!G30 -> 1099.49 | I32: ='Data Sheet'!H30 -> 1492.55 | J32: ='Data Sheet'!I30 -> 2378.51 | ... L32: ='Data Sheet'!K30 -> 2708.02 | M32: =IFERROR(SUM('Data Sheet'!H49:K49),0) -> 2707.17
B33: Net Profit % Sales | C33: =IFERROR(C32/C5,0) -> 0.03730766 | D33: =IFERROR(D32/D5,0) -> 0.04023887 | E33: =IFERROR(E32/E5,0) -> 0.053631961 | F33: =IFERROR(F32/F5,0) -> 0.045116804 | G33: =IFERROR(G32/G5,0) -> 0.052314819 | H33: =IFERROR(H32/H5,0) -> 0.045540623 | I33: =IFERROR(I32/I5,0) -> 0.048183658 | J33: =IFERROR(J32/J5,0) -> 0.055521345 | ... M33: =IFERROR(M32/M5,0) -> 0.043912912
B35: No Of Equity Share | C35: =IFERROR('Data Sheet'!B93,0) -> 56.15 | D35: =IFERROR('Data Sheet'!C93,0) -> 62.41 | E35: =IFERROR('Data Sheet'!D93,0) -> 62.41 | F35: =IFERROR('Data Sheet'!E93,0) -> 62.41 | G35: =IFERROR('Data Sheet'!F93,0) -> 64.78 | H35: =IFERROR('Data Sheet'!G93,0) -> 64.78 | I35: =IFERROR('Data Sheet'!H93,0) -> 64.78 | J35: =IFERROR('Data Sheet'!I93,0) -> 64.83 | ... L35: =IFERROR('Data Sheet'!K93,0) -> 65.07
B37: EPS | C37: =IFERROR(C32/C35,0) -> 5.7032947 | D37: =IFERROR(D32/D35,0) -> 7.6710463 | E37: =IFERROR(E32/E35,0) -> 12.918763 | F37: =IFERROR(F32/F35,0) -> 14.461465 | G37: =IFERROR(G32/G35,0) -> 20.084594 | H37: =IFERROR(H32/H35,0) -> 16.972677 | I37: =IFERROR(I32/I35,0) -> 23.04029 | J37: =IFERROR(J32/J35,0) -> 36.688416 | ... M37: =IFERROR(M32/M35,0) -> 0
B38: EPS Growth % | D38: =IFERROR(D37/C37-1,0) -> 0.34502014 | E38: =IFERROR(E37/D37-1,0) -> 0.68409399 | F38: =IFERROR(F37/E37-1,0) -> 0.11941557 | G38: =IFERROR(G37/F37-1,0) -> 0.38883541 | H38: =IFERROR(H37/G37-1,0) -> -0.15494051 | I38: =IFERROR(I37/H37-1,0) -> 0.35749302 | J38: =IFERROR(J37/I37-1,0) -> 0.5923591 | K38: =IFERROR(K37/J37-1,0) -> 0.062352378 | ... M38: =IFERROR(M37/L37-1,0) -> -1
B40: Dividend per Share | C40: =IFERROR('Data Sheet'!B31/HistoricaIFS!C35,0) -> 0 | D40: =IFERROR('Data Sheet'!C31/HistoricaIFS!D35,0) -> 0 | E40: =IFERROR('Data Sheet'!D31/HistoricaIFS!E35,0) -> 0 | F40: =IFERROR('Data Sheet'!E31/HistoricaIFS!F35,0) -> 0 | G40: =IFERROR('Data Sheet'!F31/HistoricaIFS!G35,0) -> 0 | H40: =IFERROR('Data Sheet'!G31/HistoricaIFS!H35,0) -> 0 | I40: =IFERROR('Data Sheet'!H31/HistoricaIFS!I35,0) -> 0 | J40: =IFERROR('Data Sheet'!I31/HistoricaIFS!J35,0) -> 0 | ... M40: =IFERROR('Data Sheet'!L31/HistoricaIFS!M35,0) -> 0
B41: Dividend Payout Ratio | C41: =C40/C37 -> 0 | D41: =D40/D37 -> 0 | E41: =E40/E37 -> 0 | F41: =F40/F37 -> 0 | G41: =G40/G37 -> 0 | H41: =H40/H37 -> 0 | I41: =I40/I37 -> 0 | J41: =J40/J37 -> 0 | ... L41: =L40/L37 -> 0
B43: Retained Earning | C43: =IFERROR(IF(C37>C40,1-C40,0),0) -> 1 | D43: =IFERROR(IF(D37>D40,1-D40,0),0) -> 1 | E43: =IFERROR(IF(E37>E40,1-E40,0),0) -> 1 | F43: =IFERROR(IF(F37>F40,1-F40,0),0) -> 1 | G43: =IFERROR(IF(G37>G40,1-G40,0),0) -> 1 | H43: =IFERROR(IF(H37>H40,1-H40,0),0) -> 1 | I43: =IFERROR(IF(I37>I40,1-I40,0),0) -> 1 | J43: =IFERROR(IF(J37>J40,1-J40,0),0) -> 1 | ... M43: =IFERROR(IF(M37>M40,1-M40,0),0) -> 0
B46: Balance Sheet
B47: Equity Share Capital | C47: =IFERROR('Data Sheet'!B57,0) -> 561.54 | D47: =IFERROR('Data Sheet'!C57,0) -> 624.08 | E47: =IFERROR('Data Sheet'!D57,0) -> 624.08 | F47: =IFERROR('Data Sheet'!E57,0) -> 624.08 | G47: =IFERROR('Data Sheet'!F57,0) -> 647.77 | H47: =IFERROR('Data Sheet'!G57,0) -> 647.77 | I47: =IFERROR('Data Sheet'!H57,0) -> 647.77 | J47: =IFERROR('Data Sheet'!I57,0) -> 648.26 | ... L47: =IFERROR('Data Sheet'!K57,0) -> 650.73
B48: Reserves | C48: =IFERROR('Data Sheet'!B58,0) -> 958.9 | D48: =IFERROR('Data Sheet'!C58,0) -> 3217.7 | E48: =IFERROR('Data Sheet'!D58,0) -> 4044.97 | F48: =IFERROR('Data Sheet'!E58,0) -> 4963.37 | G48: =IFERROR('Data Sheet'!F58,0) -> 10431.97 | H48: =IFERROR('Data Sheet'!G58,0) -> 11535.94 | I48: =IFERROR('Data Sheet'!H58,0) -> 13029.87 | J48: =IFERROR('Data Sheet'!I58,0) -> 15430.44 | ... L48: =IFERROR('Data Sheet'!K58,0) -> 20777.02
B49: Borrowings | C49: =IFERROR('Data Sheet'!B59,0) -> 1192.34 | D49: =IFERROR('Data Sheet'!C59,0) -> 1497.32 | E49: =IFERROR('Data Sheet'!D59,0) -> 439.25 | F49: =IFERROR('Data Sheet'!E59,0) -> 700.15 | G49: =IFERROR('Data Sheet'!F59,0) -> 333.19 | H49: =IFERROR('Data Sheet'!G59,0) -> 392.71 | I49: =IFERROR('Data Sheet'!H59,0) -> 646.94 | J49: =IFERROR('Data Sheet'!I59,0) -> 642.98 | ... L49: =IFERROR('Data Sheet'!K59,0) -> 819.62
B50: Other Liabilities | C50: =IFERROR('Data Sheet'!B60,0) -> 388.78 | D50: =IFERROR('Data Sheet'!C60,0) -> 480.18 | E50: =IFERROR('Data Sheet'!D60,0) -> 539.92 | F50: =IFERROR('Data Sheet'!E60,0) -> 717.9 | G50: =IFERROR('Data Sheet'!F60,0) -> 663.23 | H50: =IFERROR('Data Sheet'!G60,0) -> 1078.63 | I50: =IFERROR('Data Sheet'!H60,0) -> 1146.4 | J50: =IFERROR('Data Sheet'!I60,0) -> 1382.84 | ... L50: =IFERROR('Data Sheet'!K60,0) -> 2065.41
B51: Total Liablities | C51: =IFERROR('Data Sheet'!B61,0) -> 3101.56 | D51: =IFERROR('Data Sheet'!C61,0) -> 5819.28 | E51: =IFERROR('Data Sheet'!D61,0) -> 5648.22 | F51: =IFERROR('Data Sheet'!E61,0) -> 7005.5 | G51: =IFERROR('Data Sheet'!F61,0) -> 12076.16 | H51: =IFERROR('Data Sheet'!G61,0) -> 13655.05 | I51: =IFERROR('Data Sheet'!H61,0) -> 15470.98 | J51: =IFERROR('Data Sheet'!I61,0) -> 18104.52 | ... L51: =IFERROR('Data Sheet'!K61,0) -> 24312.78
B54: Fix Asset Net Block | C54: =IFERROR('Data Sheet'!B62,0) -> 2093.52 | D54: =IFERROR('Data Sheet'!C62,0) -> 2577.75 | E54: =IFERROR('Data Sheet'!D62,0) -> 3399.97 | F54: =IFERROR('Data Sheet'!E62,0) -> 4400.37 | G54: =IFERROR('Data Sheet'!F62,0) -> 5948.03 | H54: =IFERROR('Data Sheet'!G62,0) -> 7008.8 | I54: =IFERROR('Data Sheet'!H62,0) -> 9260.02 | J54: =IFERROR('Data Sheet'!I62,0) -> 11340.48 | ... L54: =IFERROR('Data Sheet'!K62,0) -> 16206.46
B55: Capital Work in Progress | C55: =IFERROR('Data Sheet'!B63,0) -> 81.69 | D55: =IFERROR('Data Sheet'!C63,0) -> 152.89 | E55: =IFERROR('Data Sheet'!D63,0) -> 147.07 | F55: =IFERROR('Data Sheet'!E63,0) -> 376.84 | G55: =IFERROR('Data Sheet'!F63,0) -> 364.4 | H55: =IFERROR('Data Sheet'!G63,0) -> 1019.59 | I55: =IFERROR('Data Sheet'!H63,0) -> 1129.34 | J55: =IFERROR('Data Sheet'!I63,0) -> 829.16 | ... L55: =IFERROR('Data Sheet'!K63,0) -> 1099.35
B56: Investments | C56: =IFERROR('Data Sheet'!B64,0) -> 29.33 | D56: =IFERROR('Data Sheet'!C64,0) -> 25.69 | E56: =IFERROR('Data Sheet'!D64,0) -> 68.18 | F56: =IFERROR('Data Sheet'!E64,0) -> 16.53 | G56: =IFERROR('Data Sheet'!F64,0) -> 14.68 | H56: =IFERROR('Data Sheet'!G64,0) -> 2.95 | I56: =IFERROR('Data Sheet'!H64,0) -> 5.94 | J56: =IFERROR('Data Sheet'!I64,0) -> 202.2 | ... L56: =IFERROR('Data Sheet'!K64,0) -> 3.26
B57: Other Assets | C57: =IFERROR('Data Sheet'!B65-SUM('Data Sheet'!B67:B69),0) -> 181.81 | D57: =IFERROR('Data Sheet'!C65-SUM('Data Sheet'!C67:C69),0) -> 209.76 | E57: =IFERROR('Data Sheet'!D65-SUM('Data Sheet'!D67:D69),0) -> 275.85 | F57: =IFERROR('Data Sheet'!E65-SUM('Data Sheet'!E67:E69),0) -> 319.67 | G57: =IFERROR('Data Sheet'!F65-SUM('Data Sheet'!F67:F69),0) -> 3674.22 | H57: =IFERROR('Data Sheet'!G65-SUM('Data Sheet'!G67:G69),0) -> 1886.27 | I57: =IFERROR('Data Sheet'!H65-SUM('Data Sheet'!H67:H69),0) -> 1967.55 | J57: =IFERROR('Data Sheet'!I65-SUM('Data Sheet'!I67:I69),0) -> 1018.71 | ... L57: =IFERROR('Data Sheet'!K65-SUM('Data Sheet'!K67:K69),0) -> 1447.35
...

Sheet Forcasting
B2: FORCASTING
B4: ='Data Sheet'!B1&" - "&'Data Sheet'!A17 -> AVENUE SUPERMARTS LTD - Sales | G4: ='Data Sheet'!B1&" - "&HistoricaIFS!B17 -> AVENUE SUPERMARTS LTD - EBITDA | L4: ='Data Sheet'!B1&" - "&HistoricaIFS!B37 -> AVENUE SUPERMARTS LTD - EPS
B5: Year Weight | C5: Year | D5: Sales | E5: Sales Growth | G5: Year Weight | H5: Year | I5: EBITDA | J5: EBITDA Growth | L5: Year Weight | M5: Year | N5: EPS | O5: EPS Growth
B6: 1 | C6: 2016 | D6: {=TRANSPOSE('Data Sheet'!B17:K17)} -> 8583.76 | G6: 1 | H6: 2016 | I6: {=TRANSPOSE(HistoricaIFS!C17:L17)} -> 664.46 | L6: 1 | M6: 2016 | N6: {=TRANSPOSE(HistoricaIFS!C37:L37)} -> 5.7032947
B7: 2 | C7: 2017 | D7: 11897.7 | E7: =IFERROR(D7/D6-1,0) -> 0.38607091 | G7: 2 | H7: 2017 | I7: 969.18 | J7: =IFERROR(I7/I6-1,0) -> 0.45859796 | L7: 2 | M7: 2017 | N7: 7.6710463 | O7: =IFERROR(N7/N6-1,0) -> 0.34502014
B8: 3 | C8: 2018 | D8: 15033.2 | E8: =IFERROR(D8/D7-1,0) -> 0.26353833 | G8: 3 | H8: 2018 | I8: 1352.86 | J8: =IFERROR(I8/I7-1,0) -> 0.39588105 | L8: 3 | M8: 2018 | N8: 12.918763 | O8: =IFERROR(N8/N7-1,0) -> 0.68409399
B9: 4 | C9: 2019 | D9: 20004.52 | E9: =IFERROR(D9/D8-1,0) -> 0.33068941 | G9: 4 | H9: 2019 | I9: 1633.31 | J9: =IFERROR(I9/I8-1,0) -> 0.20730157 | L9: 4 | M9: 2019 | N9: 14.461465 | O9: =IFERROR(N9/N8-1,0) -> 0.11941557
B10: 5 | C10: 2020 | D10: 24870.2 | E10: =IFERROR(D10/D9-1,0) -> 0.24322903 | G10: 5 | H10: 2020 | I10: 2128.31 | J10: =IFERROR(I10/I9-1,0) -> 0.30306555 | L10: 5 | M10: 2020 | N10: 20.084594 | O10: =IFERROR(N10/N9-1,0) -> 0.38883541
B11: 6 | C11: 2021 | D11: 24143.06 | E11: =IFERROR(D11/D10-1,0) -> -0.029237401 | G11: 6 | H11: 2021 | I11: 1744.83 | J11: =IFERROR(I11/I10-1,0) -> -0.18018052 | L11: 6 | M11: 2021 | N11: 16.972677 | O11: =IFERROR(N11/N10-1,0) -> -0.15494051
B12: 7 | C12: 2022 | D12: 30976.27 | E12: =IFERROR(D12/D11-1,0) -> 0.28302999 | G12: 7 | H12: 2022 | I12: 2502.35 | J12: =IFERROR(I12/I11-1,0) -> 0.43415118 | L12: 7 | M12: 2022 | N12: 23.04029 | O12: =IFERROR(N12/N11-1,0) -> 0.35749302
B13: 8 | C13: 2023 | D13: 42839.56 | E13: =IFERROR(D13/D12-1,0) -> 0.38297994 | G13: 8 | H13: 2023 | I13: 3638.77 | J13: =IFERROR(I13/I12-1,0) -> 0.45414111 | L13: 8 | M13: 2023 | N13: 36.688416 | O13: =IFERROR(N13/N12-1,0) -> 0.5923591
B14: 9 | C14: 2024 | D14: 50788.83 | E14: =IFERROR(D14/D13-1,0) -> 0.1855591 | G14: 9 | H14: 2024 | I14: 4105.64 | J14: =IFERROR(I14/I13-1,0) -> 0.12830434 | L14: 9 | M14: 2024 | N14: 38.976026 | O14: =IFERROR(N14/N13-1,0) -> 0.062352378
B15: 10 | C15: 2025 | D15: 59358.05 | E15: =IFERROR(D15/D14-1,0) -> 0.16872253 | G15: 10 | H15: 2025 | I15: 4494.51 | J15: =IFERROR(I15/I14-1,0) -> 0.094716049 | L15: 10 | M15: 2025 | N15: 41.617028 | O15: =IFERROR(N15/N14-1,0) -> 0.067759653
B16: 11 | C16: 2026 | D16: =FORECAST(B16,D6:D15,B6:B15) -> 58863.729 | E16: =IFERROR(D16/D15-1,0) -> -0.0083277781 | G16: 11 | H16: 2026 | I16: =FORECAST(G16,I6:I15,G6:G15) -> 4659.384 | J16: =IFERROR(I16/I15-1,0) -> 0.03668342 | L16: 11 | M16: 2026 | N16: =FORECAST(L16,N6:N15,L6:L15) -> 44.607736 | O16: =IFERROR(N16/N15-1,0) -> 0.071862605
B17: 12 | C17: 2027 | D17: =FORECAST(B17,D6:D16,B6:B16) -> 64320.859 | E17: =IFERROR(D17/D16-1,0) -> 0.092707852 | G17: 12 | H17: 2027 | I17: =FORECAST(G17,I7:I16,G7:G16) -> 5151.3789 | J17: =IFERROR(I17/I16-1,0) -> 0.10559227 | L17: 12 | M17: 2027 | N17: =FORECAST(L17,N7:N16,L7:L16) -> 49.429469 | O17: =IFERROR(N17/N16-1,0) -> 0.10809186
B18: 13 | C18: 2028 | D18: =FORECAST(B18,D6:D17,B6:B17) -> 69777.989 | E18: =IFERROR(D18/D17-1,0) -> 0.084842304 | G18: 13 | H18: 2028 | I18: =FORECAST(G18,I8:I17,G8:G17) -> 5655.1022 | J18: =IFERROR(I18/I17-1,0) -> 0.097784169 | L18: 13 | M18: 2028 | N18: =FORECAST(L18,N8:N17,L8:L17) -> 54.110999 | O18: =IFERROR(N18/N17-1,0) -> 0.094711326
B19: 14 | C19: 2029 | D19: =FORECAST(B19,D7:D18,B7:B18) -> 76145.401 | E19: =IFERROR(D19/D18-1,0) -> 0.091252442 | G19: 14 | H19: 2029 | I19: =FORECAST(G19,I9:I18,G9:G18) -> 6183.8163 | J19: =IFERROR(I19/I18-1,0) -> 0.093493276 | L19: 14 | M19: 2029 | N19: =FORECAST(L19,N9:N18,L9:L18) -> 59.280638 | O19: =IFERROR(N19/N18-1,0) -> 0.095537675
B20: 15 | C20: 2030 | D20: =FORECAST(B20,D8:D19,B8:B19) -> 82556.685 | E20: =IFERROR(D20/D19-1,0) -> 0.08419791 | G20: 15 | H20: 2030 | I20: =FORECAST(G20,I10:I19,G10:G19) -> 6711.9864 | J20: =IFERROR(I20/I19-1,0) -> 0.085411685 | L20: 15 | M20: 2030 | N20: =FORECAST(L20,N10:N19,L10:L19) -> 64.183371 | O20: =IFERROR(N20/N19-1,0) -> 0.082703776
B22: Arithmatic Mean | C22: =IFERROR(AVERAGE(E6:E15),0) -> 0.24606465
B23: Geometric Mean | C23: =_xlfn.RRI(B15,D6,D15) -> 0.21333355
B25: Standard Deviation | C25: =_xlfn.STDEV.S(E6:E15) -> 0.12875493

Sheet WACC
B2: Weighted Average Cost of Capital
B4: All Figures are in INR Unless satrted otherwise
B6: Peer Comps
J7: Debt / | K7: Debt/ | L7: Leverd | M7: Unleverd
B8: Name Of The Comp | F8: Country | G8: Total Debt | H8: Total Equity | I8: Tax Rate 1 | J8: Equity | K8: Capital | L8: Beta 2 | M8: Beta 3
O9: =G10 -> 819.62
B10: ='Beta - Comp '!C4 -> Avenue Super. | F10: India | G10: ='Beta - Comp '!F4 -> 819.62 | H10: ='Beta - Comp '!E4 -> 261737.44 | I10: 0.3 | J10: =G10/H10 -> 0.0031314588 | K10: =G10/(G10+H10) -> 0.0031216833 | L10: =Beta!M7 -> 1.2414891 | M10: =L10/(1+(1-I10)*J10) -> 1.2387737 | O10: =H10+G10 -> 262557.06
B11: ='Beta - Comp '!C5 -> Trent | F11: India | G11: ='Beta - Comp '!F5 -> 2237.19 | H11: ='Beta - Comp '!E5 -> 183059.4 | I11: 0.3 | J11: =G11/H11 -> 0.012221115 | K11: =G11/(G11+H11) -> 0.012073563 | L11: 1.54 | M11: =L11/(1+(1-I11)*J11) -> 1.5269374
B12: ='Beta - Comp '!C9 -> Vedant Fashions | F12: India | G12: ='Beta - Comp '!F9 -> 482.9 | H12: ='Beta - Comp '!E9 -> 19296.24 | I12: 0.3 | J12: =G12/H12 -> 0.025025601 | K12: =G12/(G12+H12) -> 0.024414611 | L12: 0.61 | M12: =L12/(1+(1-I12)*J12) -> 0.59949804 | O12: =O9/O10 -> 0.0031216833
B13: ='Beta - Comp '!C15 -> Aditya Bir. Fas. | F13: India | G13: ='Beta - Comp '!F15 -> 5016.78 | H13: ='Beta - Comp '!E15 -> 9234.98 | I13: 0.3 | J13: =G13/H13 -> 0.54323669 | K13: =G13/(G13+H13) -> 0.35201126 | L13: 0.93 | M13: =L13/(1+(1-I13)*J13) -> 0.67378332
B14: Metro Brands | F14: India | G14: ='Beta - Comp '!F17 -> 1227.08 | H14: ='Beta - Comp '!E17 -> 32844.94 | I14: 0.3 | J14: =G14/H14 -> 0.037359788 | K14: =G14/(G14+H14) -> 0.036014301 | L14: 0.79 | M14: =L14/(1+(1-I14)*J14) -> 0.76986656
H17: Average | I17: =AVERAGE(I10:I14) -> 0.3 | J17: =AVERAGE(J10:J14) -> 0.12419493 | K17: =AVERAGE(K10:K14) -> 0.085527084 | L17: =AVERAGE(L10:L14) -> 1.0222978 | M17: =AVERAGE(M10:M14) -> 0.9617718
H18: Median | I18: =MEDIAN(I10:I14) -> 0.3 | J18: =MEDIAN(J10:J14) -> 0.025025601 | K18: =MEDIAN(K10:K14) -> 0.024414611 | L18: =MEDIAN(L10:L14) -> 0.93 | M18: =MEDIAN(M10:M14) -> 0.76986656
B21: Cost Of Debt | H21: Cost Of Equity
B23: Pre -Tax Cost Of Debt | E23: 0.084 | H23: Risk Free rate | M23: 0.0739
B24: Tax Rate | E24: 0.3 | H24: Equity Risk Primium | M24: ='Rm '!G7-WACC!M23 -> 0.079448
B25: Post -Tax Cost Of Debt | E25: =E23*(1-E24) -> 0.0588 | H25: Levered Beta 4 | M25: =M34 -> 0.82026839
H26: Cost Of Equity | M26: =M23+M24*M25 -> 0.13906868
B29: Capital Structure | H29: Leveard Beta
D31: Current | E31: Target | H31: Comps Median Unleverad Beta | M31: =M18 -> 0.76986656
B32: Total Debt | C32: =G10 -> 819.62 | D32: =C32/$C$34 -> 0.0031216833 | E32: =K17 -> 0.085527084 | H32: Target Rate /Equity | M32: =E36 -> 0.093526098
B33: Market Capitalization | C33: =H10 -> 261737.44 | D33: =C33/$C$34 -> 0.99687832 | E33: =E34-E32 -> 0.91447292 | H33: =B24 -> Tax Rate | M33: =E24 -> 0.3
B34: Total Capital | C34: =C32+C33 -> 262557.06 | D34: =D32+D33 -> 1 | E34: 1 | H34: Leverad Beta | M34: =M31*(1+(1-M33)*M32) -> 0.82026839
B36: Debt / Equity | D36: =D32/D33 -> 0.0031314588 | E36: =E32/E33 -> 0.093526098
H37: =B2 -> Weighted Average Cost of Capital
B38: 1. Tax Rate considered as Marginal Tax Rate for the country
B39: 2. Levered Beta is based on 2 year Weekly data | H39: Cost Of Debt | M39: =E25 -> 0.0588
B40: 3. Unlevered Beta = Levered Beta/(1+(1-Tax Rate) x Debt/Equity) | H40: Debt Weight | M40: =E32 -> 0.085527084
B41: 3. Levered Beta = Unlevered Beta/(1+(1-Tax Rate) x Debt/Equity)
H42: Cost of Equity | M42: =M26 -> 0.13906868
H43: Equity Weight | M43: =E33 -> 0.91447292
H45: WACC | M45: =(M39*M40)+(M42*M43) -> 0.13220354

Sheet Beta
B2: Avenue Supermart Weekly Report | F2: NIFTY Returns | I2: Beta drifting | M2: Beta
B3: Date | C3: Closing Price | D3: Return | F3: Closing Price | G3: Return
B4: 44249 | C4: 2994.2 | F4: 14529.2 | I4: Leaverged Raw Beta | J4: =M4 -> 1.2414891 | L4: Beta 1 | M4: =SLOPE(D4:D108,G4:G108) -> 1.2414891
B5: 44256 | C5: 3286.1 | D5: 0.0975 | F5: 14938.1 | G5: 0.0281 | I5: Raw Beta Weight | J5: 0.75 | L5: beta2 | M5: =_xlfn.COVARIANCE.S(D4:D108,G4:G108)/_xlfn.VAR.S(G4:G108) -> 1.2414891
